<?xml version="1.0"?>
<robot name="complex_humanoid" xmlns:xacro="http://www.ros.org/wiki/xacro">

  <!-- Include Gazebo plugins -->
  <gazebo>
    <plugin name="gazebo_ros_control" filename="libgazebo_ros_control.so">
      <robotNamespace>/humanoid_robot</robotNamespace>
      <robotSimType>gazebo_ros_control/DefaultRobotHWSim</robotSimType>
    </plugin>
  </gazebo>

  <!-- Torso -->
  <link name="torso">
    <visual>
      <geometry>
        <box size="0.3 0.2 0.5"/>
      </geometry>
      <material name="gray">
        <color rgba="0.5 0.5 0.5 1"/>
      </material>
    </visual>
    <collision>
      <geometry>
        <box size="0.3 0.2 0.5"/>
      </geometry>
    </collision>
    <inertial>
      <mass value="5.0"/>
      <inertia ixx="0.1" ixy="0" ixz="0" iyy="0.1" iyz="0" izz="0.1"/>
    </inertial>
  </link>

  <!-- Gazebo properties for torso -->
  <gazebo reference="torso">
    <material>Gazebo/Gray</material>
    <mu1>0.9</mu1>
    <mu2>0.9</mu2>
  </gazebo>

  <!-- Head -->
  <joint name="neck_joint" type="revolute">
    <parent link="torso"/>
    <child link="head"/>
    <origin xyz="0 0 0.3" rpy="0 0 0"/>
    <axis xyz="0 1 0"/>
    <limit lower="-0.5" upper="0.5" effort="10" velocity="2"/>
  </joint>

  <link name="head">
    <visual>
      <geometry>
        <sphere radius="0.1"/>
      </geometry>
      <material name="skin">
        <color rgba="1 0.8 0.6 1"/>
      </material>
    </visual>
    <collision>
      <geometry>
        <sphere radius="0.1"/>
      </geometry>
    </collision>
    <inertial>
      <mass value="1.0"/>
      <inertia ixx="0.01" ixy="0" ixz="0" iyy="0.01" iyz="0" izz="0.01"/>
    </inertial>
  </link>

  <!-- Gazebo properties for head -->
  <gazebo reference="head">
    <material>Gazebo/Orange</material>
  </gazebo>

  <!-- Left Arm -->
  <joint name="left_shoulder_yaw" type="revolute">
    <parent link="torso"/>
    <child link="left_upper_arm"/>
    <origin xyz="0.15 0 0.2" rpy="0 0 0"/>
    <axis xyz="0 0 1"/>
    <limit lower="-1.57" upper="1.57" effort="30" velocity="2"/>
  </joint>

  <link name="left_upper_arm">
    <visual>
      <geometry>
        <cylinder radius="0.04" length="0.3"/>
      </geometry>
      <material name="skin">
        <color rgba="1 0.8 0.6 1"/>
      </material>
    </visual>
    <collision>
      <geometry>
        <cylinder radius="0.04" length="0.3"/>
      </geometry>
    </collision>
    <inertial>
      <mass value="0.8"/>
      <inertia ixx="0.006" ixy="0" ixz="0" iyy="0.006" iyz="0" izz="0.001"/>
    </inertial>
  </link>

  <joint name="left_shoulder_pitch" type="revolute">
    <parent link="left_upper_arm"/>
    <child link="left_forearm"/>
    <origin xyz="0 0 -0.3" rpy="0 0 0"/>
    <axis xyz="0 1 0"/>
    <limit lower="-2.356" upper="0" effort="25" velocity="2"/>
  </joint>

  <link name="left_forearm">
    <visual>
      <geometry>
        <cylinder radius="0.03" length="0.25"/>
      </geometry>
      <material name="skin">
        <color rgba="1 0.8 0.6 1"/>
      </material>
    </visual>
    <collision>
      <geometry>
        <cylinder radius="0.03" length="0.25"/>
      </geometry>
    </collision>
    <inertial>
      <mass value="0.6"/>
      <inertia ixx="0.003" ixy="0" ixz="0" iyy="0.003" iyz="0" izz="0.0005"/>
    </inertial>
  </link>

  <!-- Right Arm -->
  <joint name="right_shoulder_yaw" type="revolute">
    <parent link="torso"/>
    <child link="right_upper_arm"/>
    <origin xyz="-0.15 0 0.2" rpy="0 0 0"/>
    <axis xyz="0 0 1"/>
    <limit lower="-1.57" upper="1.57" effort="30" velocity="2"/>
  </joint>

  <link name="right_upper_arm">
    <visual>
      <geometry>
        <cylinder radius="0.04" length="0.3"/>
      </geometry>
      <material name="skin">
        <color rgba="1 0.8 0.6 1"/>
      </material>
    </visual>
    <collision>
      <geometry>
        <cylinder radius="0.04" length="0.3"/>
      </geometry>
    </collision>
    <inertial>
      <mass value="0.8"/>
      <inertia ixx="0.006" ixy="0" ixz="0" iyy="0.006" iyz="0" izz="0.001"/>
    </inertial>
  </link>

  <joint name="right_shoulder_pitch" type="revolute">
    <parent link="right_upper_arm"/>
    <child link="right_forearm"/>
    <origin xyz="0 0 -0.3" rpy="0 0 0"/>
    <axis xyz="0 1 0"/>
    <limit lower="-2.356" upper="0" effort="25" velocity="2"/>
  </joint>

  <link name="right_forearm">
    <visual>
      <geometry>
        <cylinder radius="0.03" length="0.25"/>
      </geometry>
      <material name="skin">
        <color rgba="1 0.8 0.6 1"/>
      </material>
    </visual>
    <collision>
      <geometry>
        <cylinder radius="0.03" length="0.25"/>
      </geometry>
    </collision>
    <inertial>
      <mass value="0.6"/>
      <inertia ixx="0.003" ixy="0" ixz="0" iyy="0.003" iyz="0" izz="0.0005"/>
    </inertial>
  </link>

  <!-- Transmissions for arm joints -->
  <transmission name="left_shoulder_yaw_trans">
    <type>transmission_interface/SimpleTransmission</type>
    <joint name="left_shoulder_yaw">
      <hardwareInterface>hardware_interface/EffortJointInterface</hardwareInterface>
    </joint>
    <actuator name="left_shoulder_yaw_motor">
      <hardwareInterface>hardware_interface/EffortJointInterface</hardwareInterface>
      <mechanicalReduction>1</mechanicalReduction>
    </actuator>
  </transmission>

  <transmission name="left_shoulder_pitch_trans">
    <type>transmission_interface/SimpleTransmission</type>
    <joint name="left_shoulder_pitch">
      <hardwareInterface>hardware_interface/EffortJointInterface</hardwareInterface>
    </joint>
    <actuator name="left_shoulder_pitch_motor">
      <hardwareInterface>hardware_interface/EffortJointInterface</hardwareInterface>
      <mechanicalReduction>1</mechanicalReduction>
    </actuator>
  </transmission>

  <transmission name="right_shoulder_yaw_trans">
    <type>transmission_interface/SimpleTransmission</type>
    <joint name="right_shoulder_yaw">
      <hardwareInterface>hardware_interface/EffortJointInterface</hardwareInterface>
    </joint>
    <actuator name="right_shoulder_yaw_motor">
      <hardwareInterface>hardware_interface/EffortJointInterface</hardwareInterface>
      <mechanicalReduction>1</mechanicalReduction>
    </actuator>
  </transmission>

  <transmission name="right_shoulder_pitch_trans">
    <type>transmission_interface/SimpleTransmission</type>
    <joint name="right_shoulder_pitch">
      <hardwareInterface>hardware_interface/EffortJointInterface</hardwareInterface>
    </joint>
    <actuator name="right_shoulder_pitch_motor">
      <hardwareInterface>hardware_interface/EffortJointInterface</hardwareInterface>
      <mechanicalReduction>1</mechanicalReduction>
    </actuator>
  </transmission>

  <!-- Neck joint transmission -->
  <transmission name="neck_trans">
    <type>transmission_interface/SimpleTransmission</type>
    <joint name="neck_joint">
      <hardwareInterface>hardware_interface/EffortJointInterface</hardwareInterface>
    </joint>
    <actuator name="neck_motor">
      <hardwareInterface>hardware_interface/EffortJointInterface</hardwareInterface>
      <mechanicalReduction>1</mechanicalReduction>
    </actuator>
  </transmission>

  <!-- IMU sensor -->
  <gazebo reference="torso">
    <sensor name="torso_imu" type="imu">
      <always_on>true</always_on>
      <update_rate>100</update_rate>
      <visualize>false</visualize>
      <topic>__default_topic__</topic>
      <plugin name="torso_imu_plugin" filename="libgazebo_ros_imu.so">
        <bodyName>torso</bodyName>
        <topicName>imu/data</topicName>
        <serviceName>imu/service</serviceName>
        <gaussianNoise>0.01</gaussianNoise>
        <updateRateHZ>100.0</updateRateHZ>
      </plugin>
    </sensor>
  </gazebo>

</robot>